<?xml version="1.0" ?>
<!-- =================================================================================== -->
<!-- |    This document was autogenerated by xacro from cobra_s600.xacro               | -->
<!-- |    EDITING THIS FILE BY HAND IS NOT RECOMMENDED                                 | -->
<!-- =================================================================================== -->
<robot name="adept_cobra_s600" xmlns:xacro="http://www.ros.org/wiki/xacro">
  <!-- link list -->
  <link name="base_link">
    <visual>
      <origin rpy="0 0 0" xyz="0 0 0"/>
      <geometry>
        <mesh filename="package://adept_cobra_s600_support/meshes/cobra_s600/visual/base_link.stl" scale="0.001 0.001 0.001"/>
      </geometry>
      <material name="grey">
        <color rgba=".30 .30 .30 1"/>
      </material>
    </visual>
    <collision>
      <origin rpy="0 0 0" xyz="0 0 0"/>
      <geometry>
        <mesh filename="package://adept_cobra_s600_support/meshes/cobra_s600/collision/base_link.stl" scale="0.001 0.001 0.001"/>
      </geometry>
    </collision>
  </link>
  <link name="inner_link">
    <visual>
      <origin rpy="0 0 0" xyz="0 0 0"/>
      <geometry>
        <mesh filename="package://adept_cobra_s600_support/meshes/cobra_s600/visual/link_1.stl" scale="0.001 0.001 0.001"/>
      </geometry>
      <material name="grey"/>
    </visual>
    <collision>
      <origin rpy="0 0 0" xyz="0 0 0"/>
      <geometry>
        <mesh filename="package://adept_cobra_s600_support/meshes/cobra_s600/collision/link_1.stl" scale="0.001 0.001 0.001"/>
      </geometry>
    </collision>
  </link>
  <link name="outer_link">
    <visual>
      <origin rpy="0 0 0" xyz="0 0 0"/>
      <geometry>
        <mesh filename="package://adept_cobra_s600_support/meshes/cobra_s600/visual/link_2.stl" scale="0.001 0.001 0.001"/>
      </geometry>
      <material name="grey"/>
    </visual>
    <collision>
      <origin rpy="0 0 0" xyz="0 0 0"/>
      <geometry>
        <mesh filename="package://adept_cobra_s600_support/meshes/cobra_s600/collision/link_2.stl" scale="0.001 0.001 0.001"/>
      </geometry>
    </collision>
  </link>
  <link name="quill_prismatic_link">
    <visual>
      <origin rpy="0 0 0" xyz="0 0 0"/>
      <geometry>
        <mesh filename="package://adept_cobra_s600_support/meshes/cobra_s600/visual/link_3.stl" scale="0.001 0.001 0.001"/>
      </geometry>
      <material name="grey"/>
    </visual>
    <collision>
      <origin rpy="0 0 0" xyz="0 0 0"/>
      <geometry>
        <mesh filename="package://adept_cobra_s600_support/meshes/cobra_s600/collision/link_3.stl" scale="0.001 0.001 0.001"/>
      </geometry>
    </collision>
  </link>
  <link name="quill_rotation_link">
    <visual>
      <origin rpy="0 0 0" xyz="0 0 0"/>
      <geometry>
        <mesh filename="package://adept_cobra_s600_support/meshes/cobra_s600/visual/link_4.stl" scale="0.001 0.001 0.001"/>
      </geometry>
      <material name="grey"/>
    </visual>
    <collision>
      <origin rpy="0 0 0" xyz="0 0 0"/>
      <geometry>
        <mesh filename="package://adept_cobra_s600_support/meshes/cobra_s600/collision/link_4.stl" scale="0.001 0.001 0.001"/>
      </geometry>
    </collision>
  </link>
  <link name="flyover_cable_link">
    <visual>
      <origin rpy="0 0 0" xyz="0 0 0"/>
      <geometry>
        <mesh filename="package://adept_cobra_s600_support/meshes/cobra_s600/visual/flyover_cable.stl" scale="0.001 0.001 0.001"/>
      </geometry>
      <material name="black">
        <color rgba="0 0 0 1"/>
      </material>
    </visual>
    <collision>
      <origin rpy="0 0 0" xyz="0 0 0"/>
      <geometry>
        <mesh filename="package://adept_cobra_s600_support/meshes/cobra_s600/collision/flyover_cable.stl" scale="0.001 0.001 0.001"/>
      </geometry>
    </collision>
  </link>
  <link name="tool0"/>
  <!-- end of the link list -->
  <!-- join list -->
  <joint name="inner_joint" type="revolute">
    <origin rpy="0 0 0" xyz="0 0 0.342"/>
    <parent link="base_link"/>
    <child link="inner_link"/>
    <axis xyz="0 0 1"/>
    <limit effort="100" lower="-1.8326" upper="1.8326" velocity="6.737"/>
  </joint>
  <joint name="outer_joint" type="revolute">
    <origin rpy="0 0 0" xyz="0.325 0 0"/>
    <parent link="inner_link"/>
    <child link="outer_link"/>
    <axis xyz="0 0 1"/>
    <limit effort="100" lower="-2.618" upper="2.618" velocity="12.5664"/>
  </joint>
  <joint name="quill_prismatic_joint" type="prismatic">
    <origin rpy="0 0 0" xyz="0.275 0 0.045"/>
    <parent link="outer_link"/>
    <child link="quill_prismatic_link"/>
    <axis xyz="0 0 1"/>
    <limit effort="10" lower="-0.210" upper="0" velocity="1.100"/>
  </joint>
  <joint name="quill_rotation_joint" type="revolute">
    <origin rpy="0 0 0" xyz="0 0 0"/>
    <parent link="quill_prismatic_link"/>
    <child link="quill_rotation_link"/>
    <axis xyz="0 0 -1"/>
    <limit effort="100" lower="-6.2832" upper="6.2832" velocity="20.944"/>
  </joint>
  <joint name="flyover_cable_joint" type="revolute">
    <origin rpy="0 0 0" xyz="0 0 0.550"/>
    <parent link="base_link"/>
    <child link="flyover_cable_link"/>
    <axis xyz="0 0 1"/>
    <mimic joint="inner_joint"/>
    <limit effort="100" lower="-1.8326" upper="1.8326" velocity="6.737"/>
  </joint>
  <joint name="quill_rotation_link-tool0" type="fixed">
    <parent link="quill_rotation_link"/>
    <child link="tool0"/>
    <origin rpy="3.1415926535898 0 0" xyz="0 0 0"/>
  </joint>
  <!-- end of the joint list -->
  <!-- ROS base_link to Adept World Coordinates transform -->
  <link name="base"/>
  <joint name="base_link-base" type="fixed">
    <origin rpy="0 0 0" xyz="0 0 0"/>
    <parent link="base_link"/>
    <child link="base"/>
  </joint>
</robot>
