<?xml version="1.0"?>
<robot xmlns:xacro="http://www.ros.org/wiki/xacro">

	<xacro:macro name="adept_viper_s650" params="prefix">
		<!-- link list -->
		<link name="${prefix}base_link">
    			<visual>
      				<origin xyz="0 0 0" rpy="0 0 0"/>
      				<geometry>
        				<mesh filename="package://adept_viper_s650_support/meshes/viper_s650/visual/base_link.stl" scale="0.001 0.001 0.001"/>
      				</geometry>
				<material name="grey">
					<color rgba=".30 .30 .30 1"/>
				</material>
    			</visual>
    			<collision>
      				<origin xyz="0 0 0" rpy="0 0 0"/>
      				<geometry>
        				<mesh filename="package://adept_viper_s650_support/meshes/viper_s650/collision/base_link.stl" scale="0.001 0.001 0.001"/>
      				</geometry>
    			</collision>
  		</link>

		<link name="${prefix}link_1">
			<visual>
				<origin xyz="0 0 0" rpy="0 0 0"/>
				<geometry>
					<mesh filename="package://adept_viper_s650_support/meshes/viper_s650/visual/link_1.stl" scale="0.001 0.001 0.001"/>
				</geometry>
				<material name="grey"/>
			</visual>
			<collision>
				<origin xyz="0 0 0" rpy="0 0 0"/>
				<geometry>
					<mesh filename="package://adept_viper_s650_support/meshes/viper_s650/collision/link_1.stl" scale="0.001 0.001 0.001"/>
				</geometry>
			</collision>
		</link>

		<link name="${prefix}link_2">
			<visual>
				<origin xyz="0 0 0" rpy="0 0 0"/> 
				<geometry>
					<mesh filename="package://adept_viper_s650_support/meshes/viper_s650/visual/link_2.stl" scale="0.001 0.001 0.001"/>
				</geometry>
				<material name="grey"/>
			</visual>
			<collision>
				<origin xyz="0 0 0" rpy="0 0 0"/>
				<geometry>
					<mesh filename="package://adept_viper_s650_support/meshes/viper_s650/collision/link_2.stl" scale="0.001 0.001 0.001"/>
				</geometry>
			</collision>
		</link>

		<link name="${prefix}link_3">
			<visual>
				<origin xyz="0 0 0" rpy="0 0 0"/>
				<geometry>
					<mesh filename="package://adept_viper_s650_support/meshes/viper_s650/visual/link_3.stl" scale="0.001 0.001 0.001"/>
				</geometry>
				<material name="grey"/>0,00
			</visual>
			<collision>
				<origin xyz="0 0 0" rpy="0 0 0"/>
				<geometry>
					<mesh filename="package://adept_viper_s650_support/meshes/viper_s650/collision/link_3.stl" scale="0.001 0.001 0.001"/>
				</geometry>
			</collision>
		</link>

		<link name="${prefix}link_4">
			<visual>
				<origin xyz="0 0 0" rpy="0 0 0"/>
				<geometry>
					<mesh filename="package://adept_viper_s650_support/meshes/viper_s650/visual/link_4.stl" scale="0.001 0.001 0.001"/>
				</geometry>
				<material name="grey"/>
				</visual>
			<collision>
				<origin xyz="0 0 0" rpy="0 0 0"/>
				<geometry>
					<mesh filename="package://adept_viper_s650_support/meshes/viper_s650/collision/link_4.stl" scale="0.001 0.001 0.001"/>
				</geometry>
			</collision>
		</link>

		<link name="${prefix}link_5">
			<visual>
				<origin xyz="0 0 0" rpy="0 0 0"/>
				<geometry>
					<mesh filename="package://adept_viper_s650_support/meshes/viper_s650/visual/link_5.stl" scale="0.001 0.001 0.001"/>
				</geometry>
				<material name="grey"/>
			</visual>
			<collision>
				<origin xyz="0 0 0" rpy="0 0 0"/>
				<geometry>
					<mesh filename="package://adept_viper_s650_support/meshes/viper_s650/collision/link_5.stl" scale="0.001 0.001 0.001"/>
				</geometry>
			</collision>
		</link>

		<link name="${prefix}link_6">	

			<visual>
				<origin xyz="0 0 0" rpy="0 0 0"/>
				<geometry>
					<mesh filename="package://adept_viper_s650_support/meshes/viper_s650/visual/link_6.stl" scale="0.001 0.001 0.001"/>
				</geometry>
				<material name="grey"/>
			</visual>
			<collision>
				<origin xyz="0 0 0" rpy="0 0 0"/>
				<geometry>
					<mesh filename="package://adept_viper_s650_support/meshes/viper_s650/collision/link_6.stl" scale="0.001 0.001 0.001"/>
				</geometry>
			</collision>
		</link>
    		<link name="${prefix}tool0"/>
		<!-- end of the link list -->

		<!-- join list -->
		<joint name="${prefix}joint_1" type="revolute">
			<origin xyz="0 0 0.203" rpy="0 0 0"/>
			<parent link="${prefix}base_link"/>
			<child link="${prefix}link_1"/>
			<axis xyz="0 0 1"/>
			<limit effort="0" lower="-2.9671" upper="2.9671" velocity="5.7247"/>
		</joint>

		<joint name="${prefix}joint_2" type="revolute">
			<origin xyz="0.075 0 0.132" rpy="0 0 0"/>
			<parent link="${prefix}link_1"/>
			<child link="${prefix}link_2"/>
			<axis xyz="0 1 0"/>
			<limit effort="0" lower="-3.3161" upper="0.7854" velocity="5.2360"/>
		</joint>

		<joint name="${prefix}joint_3" type="revolute">
			<origin xyz="0.270 0 0" rpy="0 0 0"/>
			<parent link="${prefix}link_2"/>
			<child link="${prefix}link_3"/>
			<axis xyz="0 1 0"/>
			<limit effort="0" lower="-0.5061" upper="4.4680" velocity="6.5450"/>
		</joint>

		<joint name="${prefix}joint_4" type="revolute">
			<origin xyz="-0.09 0 0.108" rpy="0 0 0"/>
			<parent link="${prefix}link_3"/>
			<child link="${prefix}link_4"/>
			<axis xyz="0 0 1"/>
			<limit effort="0" lower="-3.3161" upper="3.3161" velocity="6.5450"/>
		</joint>

		<joint name="${prefix}joint_5" type="revolute">
			<origin xyz="0 0 0.187" rpy="0 0 0"/>
			<parent link="${prefix}link_4"/>
			<child link="${prefix}link_5"/>
			<axis xyz="0 1 0"/>
			<limit effort="0" lower="-2.0944" upper="2.0944" velocity="6.54"/>
		</joint>

		<joint name="${prefix}joint_6" type="revolute">
			<origin xyz="0 0 0.080" rpy="0 0 0"/>
			<parent link="${prefix}link_5"/>
			<child link="${prefix}link_6"/>
			<axis xyz="0 0 1"/>
			<limit effort="0" lower="-6.2832" upper="6.2832" velocity="10.4720"/>
		</joint>
		<joint name="${prefix}joint_6-tool0" type="fixed">
			<origin xyz="0 0 0.0" rpy="0 0 0"/>
			<parent link="${prefix}link_6"/>
			<child link="${prefix}tool0"/>
        		<origin xyz="0 0 0" rpy="0 1.57079632679 0"/>
		</joint>
		<!-- end of the joint list -->

		<!-- ROS base_link to Adept World Coordinates transform -->
		<link name="${prefix}base" />
		<joint name="${prefix}base_link-base" type="fixed">
			<origin xyz="0 0 0" rpy="0 0 0"/>
			<parent link="${prefix}base_link"/>
			<child link="${prefix}base"/>
		</joint>
	</xacro:macro>
</robot>
